<?xml version="1.0" encoding="UTF-8"?>
<testsuite errors="4" failures="0" name="unittest.loader._FailedTest-20220209183818" skipped="0" tests="4" time="0.001" timestamp="2022-02-09T18:38:25">
	<testcase classname="unittest.loader._FailedTest.diplomaticpulse.tests" name="test_check_url" time="0.000" timestamp="2022-02-09T18:38:18">
		<error message="Failed to import test module: diplomaticpulse.tests.test_check_url
Traceback (most recent call last):
  File &quot;/usr/lib/python3.6/unittest/loader.py&quot;, line 428, in _find_test_path
    module = self._get_module_from_name(name)
  File &quot;/usr/lib/python3.6/unittest/loader.py&quot;, line 369, in _get_module_from_name
    __import__(name)
  File &quot;/home/alattab/projects/docker/DiplomaticPulse/diplomaticpulse/tests/test_check_url.py&quot;, line 2, in &lt;module&gt;
    import diplomaticpulse.utilities.utils as utils
  File &quot;/home/alattab/projects/docker/DiplomaticPulse/diplomaticpulse/utilities/utils.py&quot;, line 9, in &lt;module&gt;
    settings = get_project_settings()
  File &quot;/home/alattab/envs/docker/lib/python3.6/site-packages/scrapy/utils/project.py&quot;, line 69, in get_project_settings
    settings.setmodule(settings_module_path, priority='project')
  File &quot;/home/alattab/envs/docker/lib/python3.6/site-packages/scrapy/settings/__init__.py&quot;, line 287, in setmodule
    module = import_module(module)
  File &quot;/usr/lib/python3.6/importlib/__init__.py&quot;, line 126, in import_module
    return _bootstrap._gcd_import(name[level:], package, level)
  File &quot;/home/alattab/projects/docker/DiplomaticPulse/diplomaticpulse/settings.py&quot;, line 75, in &lt;module&gt;
    ELASTIC_HOST = os.environ['ELASTIC_HOST']
  File &quot;/usr/lib/python3.6/os.py&quot;, line 669, in __getitem__
    raise KeyError(key) from None
KeyError: 'ELASTIC_HOST'
" type="ImportError">
<![CDATA[ImportError: Failed to import test module: diplomaticpulse.tests.test_check_url
Traceback (most recent call last):
  File "/usr/lib/python3.6/unittest/loader.py", line 428, in _find_test_path
    module = self._get_module_from_name(name)
  File "/usr/lib/python3.6/unittest/loader.py", line 369, in _get_module_from_name
    __import__(name)
  File "/home/alattab/projects/docker/DiplomaticPulse/diplomaticpulse/tests/test_check_url.py", line 2, in <module>
    import diplomaticpulse.utilities.utils as utils
  File "/home/alattab/projects/docker/DiplomaticPulse/diplomaticpulse/utilities/utils.py", line 9, in <module>
    settings = get_project_settings()
  File "/home/alattab/envs/docker/lib/python3.6/site-packages/scrapy/utils/project.py", line 69, in get_project_settings
    settings.setmodule(settings_module_path, priority='project')
  File "/home/alattab/envs/docker/lib/python3.6/site-packages/scrapy/settings/__init__.py", line 287, in setmodule
    module = import_module(module)
  File "/usr/lib/python3.6/importlib/__init__.py", line 126, in import_module
    return _bootstrap._gcd_import(name[level:], package, level)
  File "/home/alattab/projects/docker/DiplomaticPulse/diplomaticpulse/settings.py", line 75, in <module>
    ELASTIC_HOST = os.environ['ELASTIC_HOST']
  File "/usr/lib/python3.6/os.py", line 669, in __getitem__
    raise KeyError(key) from None
KeyError: 'ELASTIC_HOST'

]]>		</error>
	</testcase>
	<testcase classname="unittest.loader._FailedTest.diplomaticpulse.tests" name="test_get_language" time="0.000" timestamp="2022-02-09T18:38:20">
		<error message="Failed to import test module: diplomaticpulse.tests.test_get_language
Traceback (most recent call last):
  File &quot;/usr/lib/python3.6/unittest/loader.py&quot;, line 428, in _find_test_path
    module = self._get_module_from_name(name)
  File &quot;/usr/lib/python3.6/unittest/loader.py&quot;, line 369, in _get_module_from_name
    __import__(name)
  File &quot;/home/alattab/projects/docker/DiplomaticPulse/diplomaticpulse/tests/test_get_language.py&quot;, line 2, in &lt;module&gt;
    import diplomaticpulse.utilities.utils as utils
  File &quot;/home/alattab/projects/docker/DiplomaticPulse/diplomaticpulse/utilities/utils.py&quot;, line 9, in &lt;module&gt;
    settings = get_project_settings()
  File &quot;/home/alattab/envs/docker/lib/python3.6/site-packages/scrapy/utils/project.py&quot;, line 69, in get_project_settings
    settings.setmodule(settings_module_path, priority='project')
  File &quot;/home/alattab/envs/docker/lib/python3.6/site-packages/scrapy/settings/__init__.py&quot;, line 287, in setmodule
    module = import_module(module)
  File &quot;/usr/lib/python3.6/importlib/__init__.py&quot;, line 126, in import_module
    return _bootstrap._gcd_import(name[level:], package, level)
  File &quot;/home/alattab/projects/docker/DiplomaticPulse/diplomaticpulse/settings.py&quot;, line 75, in &lt;module&gt;
    ELASTIC_HOST = os.environ['ELASTIC_HOST']
  File &quot;/usr/lib/python3.6/os.py&quot;, line 669, in __getitem__
    raise KeyError(key) from None
KeyError: 'ELASTIC_HOST'
" type="ImportError">
<![CDATA[ImportError: Failed to import test module: diplomaticpulse.tests.test_get_language
Traceback (most recent call last):
  File "/usr/lib/python3.6/unittest/loader.py", line 428, in _find_test_path
    module = self._get_module_from_name(name)
  File "/usr/lib/python3.6/unittest/loader.py", line 369, in _get_module_from_name
    __import__(name)
  File "/home/alattab/projects/docker/DiplomaticPulse/diplomaticpulse/tests/test_get_language.py", line 2, in <module>
    import diplomaticpulse.utilities.utils as utils
  File "/home/alattab/projects/docker/DiplomaticPulse/diplomaticpulse/utilities/utils.py", line 9, in <module>
    settings = get_project_settings()
  File "/home/alattab/envs/docker/lib/python3.6/site-packages/scrapy/utils/project.py", line 69, in get_project_settings
    settings.setmodule(settings_module_path, priority='project')
  File "/home/alattab/envs/docker/lib/python3.6/site-packages/scrapy/settings/__init__.py", line 287, in setmodule
    module = import_module(module)
  File "/usr/lib/python3.6/importlib/__init__.py", line 126, in import_module
    return _bootstrap._gcd_import(name[level:], package, level)
  File "/home/alattab/projects/docker/DiplomaticPulse/diplomaticpulse/settings.py", line 75, in <module>
    ELASTIC_HOST = os.environ['ELASTIC_HOST']
  File "/usr/lib/python3.6/os.py", line 669, in __getitem__
    raise KeyError(key) from None
KeyError: 'ELASTIC_HOST'

]]>		</error>
	</testcase>
	<testcase classname="unittest.loader._FailedTest.diplomaticpulse.tests" name="test_get_url_extension" time="0.001" timestamp="2022-02-09T18:38:25">
		<error message="Failed to import test module: diplomaticpulse.tests.test_get_url_extension
Traceback (most recent call last):
  File &quot;/usr/lib/python3.6/unittest/loader.py&quot;, line 428, in _find_test_path
    module = self._get_module_from_name(name)
  File &quot;/usr/lib/python3.6/unittest/loader.py&quot;, line 369, in _get_module_from_name
    __import__(name)
  File &quot;/home/alattab/projects/docker/DiplomaticPulse/diplomaticpulse/tests/test_get_url_extension.py&quot;, line 2, in &lt;module&gt;
    import diplomaticpulse.utilities.utils as utils
  File &quot;/home/alattab/projects/docker/DiplomaticPulse/diplomaticpulse/utilities/utils.py&quot;, line 9, in &lt;module&gt;
    settings = get_project_settings()
  File &quot;/home/alattab/envs/docker/lib/python3.6/site-packages/scrapy/utils/project.py&quot;, line 69, in get_project_settings
    settings.setmodule(settings_module_path, priority='project')
  File &quot;/home/alattab/envs/docker/lib/python3.6/site-packages/scrapy/settings/__init__.py&quot;, line 287, in setmodule
    module = import_module(module)
  File &quot;/usr/lib/python3.6/importlib/__init__.py&quot;, line 126, in import_module
    return _bootstrap._gcd_import(name[level:], package, level)
  File &quot;/home/alattab/projects/docker/DiplomaticPulse/diplomaticpulse/settings.py&quot;, line 75, in &lt;module&gt;
    ELASTIC_HOST = os.environ['ELASTIC_HOST']
  File &quot;/usr/lib/python3.6/os.py&quot;, line 669, in __getitem__
    raise KeyError(key) from None
KeyError: 'ELASTIC_HOST'
" type="ImportError">
<![CDATA[ImportError: Failed to import test module: diplomaticpulse.tests.test_get_url_extension
Traceback (most recent call last):
  File "/usr/lib/python3.6/unittest/loader.py", line 428, in _find_test_path
    module = self._get_module_from_name(name)
  File "/usr/lib/python3.6/unittest/loader.py", line 369, in _get_module_from_name
    __import__(name)
  File "/home/alattab/projects/docker/DiplomaticPulse/diplomaticpulse/tests/test_get_url_extension.py", line 2, in <module>
    import diplomaticpulse.utilities.utils as utils
  File "/home/alattab/projects/docker/DiplomaticPulse/diplomaticpulse/utilities/utils.py", line 9, in <module>
    settings = get_project_settings()
  File "/home/alattab/envs/docker/lib/python3.6/site-packages/scrapy/utils/project.py", line 69, in get_project_settings
    settings.setmodule(settings_module_path, priority='project')
  File "/home/alattab/envs/docker/lib/python3.6/site-packages/scrapy/settings/__init__.py", line 287, in setmodule
    module = import_module(module)
  File "/usr/lib/python3.6/importlib/__init__.py", line 126, in import_module
    return _bootstrap._gcd_import(name[level:], package, level)
  File "/home/alattab/projects/docker/DiplomaticPulse/diplomaticpulse/settings.py", line 75, in <module>
    ELASTIC_HOST = os.environ['ELASTIC_HOST']
  File "/usr/lib/python3.6/os.py", line 669, in __getitem__
    raise KeyError(key) from None
KeyError: 'ELASTIC_HOST'

]]>		</error>
	</testcase>
	<testcase classname="unittest.loader._FailedTest.diplomaticpulse.tests" name="test_pdf_parser" time="0.000" timestamp="2022-02-09T18:38:25">
		<error message="Failed to import test module: diplomaticpulse.tests.test_pdf_parser
Traceback (most recent call last):
  File &quot;/usr/lib/python3.6/unittest/loader.py&quot;, line 428, in _find_test_path
    module = self._get_module_from_name(name)
  File &quot;/usr/lib/python3.6/unittest/loader.py&quot;, line 369, in _get_module_from_name
    __import__(name)
  File &quot;/home/alattab/projects/docker/DiplomaticPulse/diplomaticpulse/tests/test_pdf_parser.py&quot;, line 2, in &lt;module&gt;
    import diplomaticpulse.parsers.pdf_parser as pdf_parser
  File &quot;/home/alattab/projects/docker/DiplomaticPulse/diplomaticpulse/parsers/pdf_parser.py&quot;, line 20, in &lt;module&gt;
    import fitz
  File &quot;/home/alattab/envs/docker/lib/python3.6/site-packages/fitz/__init__.py&quot;, line 1, in &lt;module&gt;
    from frontend import *
ModuleNotFoundError: No module named 'frontend'
" type="ImportError">
<![CDATA[ImportError: Failed to import test module: diplomaticpulse.tests.test_pdf_parser
Traceback (most recent call last):
  File "/usr/lib/python3.6/unittest/loader.py", line 428, in _find_test_path
    module = self._get_module_from_name(name)
  File "/usr/lib/python3.6/unittest/loader.py", line 369, in _get_module_from_name
    __import__(name)
  File "/home/alattab/projects/docker/DiplomaticPulse/diplomaticpulse/tests/test_pdf_parser.py", line 2, in <module>
    import diplomaticpulse.parsers.pdf_parser as pdf_parser
  File "/home/alattab/projects/docker/DiplomaticPulse/diplomaticpulse/parsers/pdf_parser.py", line 20, in <module>
    import fitz
  File "/home/alattab/envs/docker/lib/python3.6/site-packages/fitz/__init__.py", line 1, in <module>
    from frontend import *
ModuleNotFoundError: No module named 'frontend'

]]>		</error>
	</testcase>
	<system-out>
<![CDATA[]]>	</system-out>
	<system-err>
<![CDATA[]]>	</system-err>
</testsuite>
